<?xml version="1.0"?>
<robot name="barracuda">

	<material name="grey">
		<color rgba="0.75 0.75 0.75 1"/>
	</material>
	<material name="blue">
		<color rgba="0 0 0.8 1"/>
	</material>
	<material name="red">
		<color rgba="0.8 0 0 1"/>
	</material>
	<material name="green">
		<color rgba="0 0.8 0 1"/>
	</material>

	<gazebo>
		<plugin name="gazebo_ros_control" filename="libgazebo_ros_control.so">
			<robotNamespace>/barracuda</robotNamespace>
		</plugin>
	</gazebo>


	<link name="base_link">
    		<inertial>
			<origin xyz="0 0 0" rpy="0 0 0"/>
        		<mass value="3.2" />
        		<inertia ixx="4.46666666667e-02" ixy="0.0" ixz="0.0" iyy="4.46666666667e-02" iyz="0.0" izz="4e-04"/>
    		</inertial>
    		<collision>
        		<origin xyz="0 -0.2 0" rpy="1.6 0 0"/>
			<geometry>
            			<cylinder radius="0.05" length="0.4"/>
        		</geometry>
    		</collision>
        	<visual>
        		<origin rpy="1.6 0 0" xyz="0 -0.2 0"/>
        		<geometry>
            			<cylinder radius="0.05" length="0.4"/>
        		</geometry>
			<material name="grey"/>
        	</visual>
	</link>

	<gazebo reference="base_link">
		<kp>100000.0</kp>
		<kd>100000.0</kd>
		<mu1>10.0</mu1>
		<mu2>10.0</mu2>
		<material>Gazebo/Grey</material>
	</gazebo>

	<link name="second_link">
		<inertial>
			<origin xyz="0 0 0" rpy="0 0 0"/>
        		<mass value="0.85" />
        		<inertia ixx="6.56625e-03" ixy="0.0" ixz="0.0" iyy="6.56625e-03" iyz="0.0" izz="3.825e-04"/>
    		</inertial>
    		<collision>
        		<origin xyz="0 0 0" rpy="1.6 0 0"/>
        		<geometry>
				<cylinder radius="0.03" length="0.3"/>
        		</geometry>
    		</collision>
        	<visual>
        		<origin rpy="1.6 0 0" xyz="0 0 0"/>
        		<geometry>
            			<cylinder radius="0.03" length="0.3"/>
        		</geometry>
			<material name="grey"/>
        	</visual>
	</link>  

	<gazebo reference="second_link">
		<kp>100000.0</kp>
		<kd>100000.0</kd>
		<mu1>10.0</mu1>
 		<mu2>10.0</mu2>
		<material>Gazebo/Grey</material>
	</gazebo>

	<joint name="middle_joint" type="fixed">
		<parent link="base_link"/>
		<child link="second_link"/>
		<origin xyz="0 -0.55 -0.01" rpy="0 0 0"/>
	</joint>

	<link name="ball_link">
		<inertial>
			<origin xyz="0 0 0" rpy="0 0 0"/>
			<mass value="0.1" />
			<inertia ixx="3.6e-05" ixy="0.0" ixz="0.0" iyy="3.6e-05" iyz="0.0" izz="3.6e-05"/>
		</inertial>
		<collision>
			<origin xyz="0 0 0" rpy="0 0 0"/>
			<geometry>
				<sphere radius="0.03"/>
			</geometry>
		</collision>
		<visual>
			<origin rpy="0 0 0" xyz="0 0 0"/>
			<geometry>
				<sphere radius="0.03"/>
			</geometry>
			<material name="green"/>
		</visual>
	</link>

	<gazebo reference="ball_link">
		<kp>100000.0</kp>
		<kd>100000.0</kd>
		<mu1>10.0</mu1>
		<mu2>10.0</mu2>
		<material>Gazebo/Green</material>
	</gazebo>
    
	<joint name="ball_joint" type="fixed">
		<parent link="second_link"/>
		<child link="ball_link"/>
		<origin xyz="0 -0.15 -0.004" rpy="0 0 0"/>
	</joint>

	<link name="midball_link">
		<inertial>
			<origin xyz="0 0 0" rpy="0 0 0"/>
			<mass value="0.5" />
			<inertia ixx="5e-04" ixy="0.0" ixz="0.0" iyy="5e-04" iyz="0.0" izz="5e-04"/>
		</inertial>
		<visual>
			<origin rpy="0 0 0" xyz="0 0 0"/>
        		<geometry>
                		<sphere radius="0.05"/>
        		</geometry>
			<material name="grey"/>
        	</visual>
	</link>

	<gazebo reference="midball_link">
		<kp>100000.0</kp>
		<kd>100000.0</kd>
		<mu1>10.0</mu1>
		<mu2>10.0</mu2>
		<material>Gazebo/Grey</material>
	</gazebo>
    
	<joint name="midball_joint" type="fixed">
		<parent link="base_link"/>
		<child link="midball_link"/>
		<origin xyz="0 -0.4 -0.005" rpy="0 0 0"/>
	</joint>  

	<link name="fin_vup"> fins
		<inertial>
			<origin xyz="0 0 0" rpy="0 0 0"/>
			<mass value="0.005" />
			<inertia ixx="2.08333333333e-06" ixy="0.0" ixz="0.0" iyy="1.04333333333e-06" iyz="0.0" izz="1.04333333333e-06"/>
		</inertial>
		<visual>
			<origin rpy="0 0 0" xyz="0 -0.05 0.05"/>
			<geometry>
				<box size="0.002 0.05 0.05"/> x-length,y-legth and z-length
			</geometry>
			<material name="red"/>
		</visual>
	</link>

	<gazebo reference="fin_vup">
		<kp>100000.0</kp>
		<kd>100000.0</kd>
		<mu1>10.0</mu1>
		<mu2>10.0</mu2>
		<material>Gazebo/Red</material>
	</gazebo>

	<joint name="fin_vup_joint" type="revolute">
		<parent link="base_link"/>
		<child link="fin_vup"/>
		<origin xyz="0 0 0.05" rpy="0 0 0"/>
		<limit lower="-0.2" upper="0.2" effort="0.1" velocity="0.005"/>
		<axis xyz="0 0 1"/>
	</joint>

	<transmission name="tran1">
		<type>transmission_interface/SimpleTransmission</type>
		<joint name="fin_vup_joint">
			<hardwareInterface>EffortJointInterface</hardwareInterface>
		</joint>
		<actuator name="motor1">
			<hardwareInterface>EffortJointInterface</hardwareInterface>
			<mechanicalReduction>1</mechanicalReduction>
		</actuator>
	</transmission>

	<link name="fin_vdown">
		<inertial>
			<origin xyz="0 0 0" rpy="0 0 0"/>
			<mass value="0.005" />
		<inertia ixx="2.08333333333e-06" ixy="0.0" ixz="0.0" iyy="1.04333333333e-06" iyz="0.0" izz="1.04333333333e-06"/>
		</inertial>
		<visual>
			<origin rpy="0 0 0" xyz="0 -0.05 -0.05"/>
			<geometry>
				<box size="0.002 0.05 0.05"/> x-length,y-legth and z-length
			</geometry>
			<material name="red"/>
		</visual>
	</link>

	<gazebo reference="fin_vdown">
		<kp>100000.0</kp>
		<kd>100000.0</kd>
		<mu1>10.0</mu1>
		<mu2>10.0</mu2>
		<material>Gazebo/Red</material>
	</gazebo>

	<joint name="fin_vdown_joint" type="revolute">
		<parent link="base_link"/>
		<child link="fin_vdown"/>
		<origin xyz="0 0 -0.05" rpy="0 0 0"/>
		<limit lower="-0.2" upper="0.2" effort="0.1" velocity="0.005"/>
		<axis xyz="0 0 -1"/>
	</joint>

	<transmission name="tran2">
		<type>transmission_interface/SimpleTransmission</type>
		<joint name="fin_vdown_joint">
			<hardwareInterface>EffortJointInterface</hardwareInterface>
		</joint>
		<actuator name="motor2">
			<hardwareInterface>EffortJointInterface</hardwareInterface>
			<mechanicalReduction>1</mechanicalReduction>
		</actuator>
	</transmission>

	<link name="fin_vright">
		<inertial>
			<origin xyz="0 0 0" rpy="0 0 0"/>
			<mass value="0.005" />
			<inertia ixx="1.04333333333e-06" ixy="0.0" ixz="0.0" iyy="1.04333333333e-06" iyz="0.0" izz="2.08333333333e-06"/>
		</inertial>
		<visual>
			<origin rpy="0 0 0" xyz="-0.05 -0.05 0"/>
			<geometry>
				<box size="0.05 0.05 0.002"/> x-length,y-legth and z-length
			</geometry>
			<material name="red"/>
		</visual>
	</link>

	<gazebo reference="fin_vright">
		<kp>100000.0</kp>
		<kd>100000.0</kd>
		<mu1>10.0</mu1>
		<mu2>10.0</mu2>
		<material>Gazebo/Red</material>
	</gazebo>

	<joint name="fin_vright_joint" type="revolute">
		<parent link="base_link"/>
		<child link="fin_vright"/>
		<origin xyz="-0.05 0 0" rpy="0 0 0"/>
		<limit lower="-0.2" upper="0.2" effort="0.1" velocity="0.005"/>
		<axis xyz="-1 0 0"/>
	</joint>

	<transmission name="tran3">
		<type>transmission_interface/SimpleTransmission</type>
		<joint name="fin_vright_joint">
			<hardwareInterface>EffortJointInterface</hardwareInterface>
		</joint>
		<actuator name="motor3">
			<hardwareInterface>EffortJointInterface</hardwareInterface>
			<mechanicalReduction>1</mechanicalReduction>
		</actuator>
	</transmission>

	<link name="fin_vleft">
		<inertial>
			<origin xyz="0 0 0" rpy="0 0 0"/>
			<mass value="0.005" />
			<inertia ixx="1.04333333333e-06" ixy="0.0" ixz="0.0" iyy="1.04333333333e-06" iyz="0.0" izz="2.08333333333e-06"/>
		</inertial>
		<visual>
			<origin rpy="0 0 0" xyz="0.05 -0.05 0"/>
			<geometry>
				<box size="0.05 0.05 0.002"/> x-length,y-legth and z-length
			</geometry>
			<material name="red"/>
		</visual>
	</link>

	<gazebo reference="fin_vleft">
		<kp>100000.0</kp>
		<kd>100000.0</kd>
		<mu1>10.0</mu1>
		<mu2>10.0</mu2>
		<material>Gazebo/Red</material>
	</gazebo>

	<joint name="fin_vleft_joint" type="revolute">
		<parent link="base_link"/>
		<child link="fin_vleft"/>
		<origin xyz="0.05 0 0" rpy="0 0 0"/>
		<limit lower="-0.2" upper="0.2" effort="0.1" velocity="0.005"/>
		<axis xyz="1 0 0"/>
	</joint>

	<transmission name="tran4">
		<type>transmission_interface/SimpleTransmission</type>
		<joint name="fin_vleft_joint">
			<hardwareInterface>EffortJointInterface</hardwareInterface>
		</joint>
		<actuator name="motor4">
			<hardwareInterface>EffortJointInterface</hardwareInterface>
			<mechanicalReduction>1</mechanicalReduction>
		</actuator>
	</transmission>

	<link name="frontfin_vup"> front fins
		<inertial>
			<origin xyz="0 0 0" rpy="0 0 0"/>
			<mass value="0.003" />
			<inertia ixx="4.5e-07" ixy="0.0" ixz="0.0" iyy="2.26e-07" iyz="0.0" izz="2.26e-07"/>
		</inertial>
		<visual>
			<origin rpy="0 0 0" xyz="0 0 0"/>
			<geometry>
				<box size="0.002 0.03 0.03"/> x-length,y-legth and z-length
			</geometry>
			<material name="blue"/>
		</visual>
	</link>

	<gazebo reference="frontfin_vup">
		<kp>100000.0</kp>
		<kd>100000.0</kd>
		<mu1>10.0</mu1>
		<mu2>10.0</mu2>
		<material>Gazebo/Blue</material>
	</gazebo>

	<joint name="frontfin_vup_joint" type="fixed">
		<parent link="second_link"/>
		<child link="frontfin_vup"/>
		<origin xyz="0 -0.05 0.03" rpy="0 0 0"/>
	</joint>

	<link name="frontfin_vdown">
		<inertial>
			<origin xyz="0 0 0" rpy="0 0 0"/>
			<mass value="0.003" />
			<inertia ixx="4.5e-07" ixy="0.0" ixz="0.0" iyy="2.26e-07" iyz="0.0" izz="2.26e-07"/>
		</inertial>
		<visual>
			<origin rpy="0 0 0" xyz="0 0 0"/>
			<geometry>
				<box size="0.002 0.03 0.03"/> x-length,y-legth and z-length
			</geometry>
			<material name="blue"/>
		</visual>
	</link>

	<gazebo reference="frontfin_vdown">
		<kp>100000.0</kp>
		<kd>100000.0</kd>
		<mu1>10.0</mu1>
		<mu2>10.0</mu2>
		<material>Gazebo/Blue</material>
	</gazebo>

	<joint name="frontfin_vdown_joint" type="fixed">
		<parent link="second_link"/>
		<child link="frontfin_vdown"/>
		<origin xyz="0 -0.05 -0.03" rpy="0 0 0"/>
	</joint>

	<link name="frontfin_vright">
		<inertial>
			<origin xyz="0 0 0" rpy="0 0 0"/>
			<mass value="0.003" />
			<inertia ixx="2.26e-07" ixy="0.0" ixz="0.0" iyy="2.26e-07" iyz="0.0" izz="4.5e-07"/>
		</inertial>
		<visual>
			<origin rpy="0 0 0" xyz="0 0 0"/>
			<geometry>
				<box size="0.03 0.03 0.002"/> x-length,y-legth and z-length
			</geometry>
			<material name="blue"/>
		</visual>
	</link>

	<gazebo reference="frontfin_vright">
		<kp>100000.0</kp>
		<kd>100000.0</kd>
		<mu1>10.0</mu1>
		<mu2>10.0</mu2>
		<material>Gazebo/Blue</material>
	</gazebo>

	<joint name="frontfin_vright_joint" type="fixed">
		<parent link="second_link"/>
		<child link="frontfin_vright"/>
		<origin xyz="-0.05 -0.05 0" rpy="0 0 0"/>
	</joint>

	<link name="frontfin_vleft">
		<inertial>
			<origin xyz="0 0 0" rpy="0 0 0"/>
			<mass value="0.003" />
			<inertia ixx="2.26e-07" ixy="0.0" ixz="0.0" iyy="2.26e-07" iyz="0.0" izz="4.5e-07"/>
		</inertial>
		<visual>
			<origin rpy="0 0 0" xyz="0 0 0"/>
			<geometry>
				<box size="0.03 0.03 0.002"/> x-length,y-legth and z-length
			</geometry>
			<material name="blue"/>
		</visual>
	</link>

	<gazebo reference="frontfin_vleft">
		<kp>100000.0</kp>
		<kd>100000.0</kd>
		<mu1>10.0</mu1>
		<mu2>10.0</mu2>
		<material>Gazebo/Blue</material>
	</gazebo>

	<joint name="frontfin_vleft_joint" type="fixed">
		<parent link="second_link"/>
		<child link="frontfin_vleft"/>
		<origin xyz="0.05 -0.05 0" rpy="0 0 0"/>
	</joint>

	<link name="camera_link"> camera
		<inertial>
			<origin xyz="0 0 0" rpy="0 0 0"/>
			<mass value="0.001" />
			<inertia ixx="9.1875e-09" ixy="0.0" ixz="0.0" iyy="9.1875e-09" iyz="0.0" izz="1.378125e-08"/>
		</inertial>
		<visual>
			<origin rpy="0.0 0 0" xyz="0 0 0"/>
			<geometry>
				<box size="0.0005 0.0005 0.0005"/>
			</geometry>
			<material name="red"/>
		</visual>
	</link>

	<gazebo reference="camera_link">
		<material>Gazebo/Red</material>
	</gazebo>

	<joint name="camera_joint" type="fixed">
		<parent link="ball_link"/>
		<child link="camera_link"/>
		<origin xyz="0 -0.03 0" rpy="0 0 0"/>
	</joint>

<!-- camera -->
	<gazebo reference="camera_link">
		<sensor type="camera" name="camera1">
			<update_rate>15.0</update_rate>
			<camera name="head">

					<pose>0 0 0 0 0 0</pose>

				<horizontal_fov>1.3962634</horizontal_fov>
				<image>
					<width>400</width>
					<height>400</height>
					<format>R8G8B8</format>
				</image>
				<clip>
					<near>0.01</near>
					<far>100</far>
				</clip>
				<noise>
					<type>gaussian</type>
					<stddev>0.007</stddev>
				</noise>
			</camera>
			<plugin name="camera_controller" filename="libgazebo_ros_camera.so">
				<alwaysOn>true</alwaysOn>
				<updateRate>0.0</updateRate>
				<cameraName>barracuda/camera1</cameraName>
				<imageTopicName>image_raw</imageTopicName>
				<cameraInfoTopicName>camera_info</cameraInfoTopicName>
				<frameName>camera_link</frameName>
				<hackBaseline>0.07</hackBaseline>
				<distortionK1>0.0</distortionK1>
				<distortionK2>0.0</distortionK2>
				<distortionK3>0.0</distortionK3>
				<distortionT1>0.0</distortionT1>
				<distortionT2>0.0</distortionT2>
			</plugin>
		</sensor>
	</gazebo>
</robot>
